Workbook

Sheet list
B1: CHORAKLIK NATIJALAR | R1: _________________ kuni olingan ____BSB/Loyiha ishi NATIJALARI | AC1: _________________ kuni olingan ____BSB/Loyiha ishi NATIJALARI | AN1: _________________ kuni olingan ____BSB/Loyiha ishi NATIJALARI | AY1: _________________ kuni olingan ____BSB/Loyiha ishi NATIJALARI | BJ1: _________________ kuni olingan ____CHSB NATIJALARI | CC1: _________________ kuni olingan ____CHSB NATIJALARI
B2: fan | D2: chorak | F2: sinf | R2: =$B$2 -> fan | S2: =$C$2 -> 0 | T2: =$D$2 -> chorak | U2: =$E$2 -> 0 | V2: =$F$2 -> sinf | W2: =$G$2 -> 0 | AA2: =IF(MAX(AA6:AA45)>40,50,IF(MAX(AA6:AA45)>20,25,IF(MAX(AA6:AA45)>15,20,IF(MAX(AA6:AA45)>8,10)))) -> FALSE | AB2: ball | AC2: =$B$2 -> fan | AD2: =$C$2 -> 0 | AE2: =$D$2 -> chorak | AF2: =$E$2 -> 0 | AG2: =$F$2 -> sinf | AH2: =$G$2 -> 0 | AL2: =IF(MAX(AL6:AL45)>40,50,IF(MAX(AL6:AL45)>20,25,IF(MAX(AL6:AL45)>15,20,IF(MAX(AL6:AL45)>8,10)))) -> FALSE | AM2: ball | AN2: =$B$2 -> fan | AO2: =$C$2 -> 0 | AP2: =$D$2 -> chorak | AQ2: =$E$2 -> 0 | AR2: =$F$2 -> sinf | AS2: =$G$2 -> 0 | AW2: =IF(MAX(AW6:AW45)>40,50,IF(MAX(AW6:AW45)>20,25,IF(MAX(AW6:AW45)>15,20,IF(MAX(AW6:AW45)>8,10)))) -> FALSE | AX2: ball | AY2: =$B$2 -> fan | AZ2: =$C$2 -> 0 | BA2: =$D$2 -> chorak | BB2: =$E$2 -> 0 | BC2: =$F$2 -> sinf | BD2: =$G$2 -> 0 | BH2: =IF(MAX(BH6:BH45)>40,50,IF(MAX(BH6:BH45)>20,25,IF(MAX(BH6:BH45)>15,20,IF(MAX(BH6:BH45)>8,10)))) -> FALSE | BI2: ball | BJ2: fan | BK2: =$C$2 -> 0 | BL2: chorak | BO2: =$E$2 -> 0 | BR2: sinf | BT2: =$G$2 -> 0 | CA2: 40 | CB2: ball | CC2: fan | CD2: =$C$2 -> 0 | CE2: ="chorak: "&$E$2 -> chorak: | CG2: ="sinf: "& $G$2 -> sinf: | CH2: 40 | CI2: ball
B4: T/r | C4: F.I.SH | D4: summativ baholash bo'yicha ballar | O4: chorak bahosi | P4: fan | Q4: =IF(ISBLANK(C2),"",C2) | R4: T/r | S4: F.I.SH | T4: Baholash mezoni | AA4: Jami ball | AB4: Foizda | AC4: T/r | AD4: F.I.SH | AE4: Baholash mezoni | AL4: Jami ball | AM4: Foizda | AN4: T/r | AO4: F.I.SH | AP4: Baholash mezoni | AW4: Jami ball | AX4: Foizda | AY4: T/r | AZ4: F.I.SH | BA4: Baholash mezoni | BH4: Jami ball | BI4: Foizda | BJ4: T/r | BK4: F.I.SH | BL4: Baholash mezoni | CA4: Jami ball 40 | CB4: Foizda | CC4: T/r | CD4: F.I.SH | CE4: Baholash mezoni | CH4: Jami ball 40 | CI4: Foizda
D5: BSB | E5: BSB | F5: BSB | G5: LI/Lab | H5: FB (10) | I5: CHSB (40) | J5: Jami ball (100) | N5: tahlil % da | T5: 1 | U5: 2 | V5: 3 | W5: 4 | X5: 5 | Y5: 6 | Z5: 7 | AE5: 1 | AF5: 2 | AG5: 3 | AH5: 4 | AI5: 5 | AJ5: 6 | AK5: 7 | AP5: 1 | AQ5: 2 | AR5: 3 | AS5: 4 | AT5: 5 | AU5: 6 | AV5: 7 | BA5: 1 | BB5: 2 | BC5: 3 | BD5: 4 | BE5: 5 | BF5: 6 | BG5: 7 | BL5: 1 | BM5: 2 | BN5: 3 | BO5: 4 | BP5: 5 | BQ5: 6 | BR5: 7 | BS5: 8 | BT5: 9 | BU5: 10 | BV5: 11 | BW5: 12 | BX5: 13 | BY5: 14 | BZ5: 15 | CE5: "Bilish (to'g'ri javoblar soni)" | CF5: "qo'llash (to'g'ri javoblar soni)" | CG5: "Mulohaza (to'g'ri javoblar soni)"
B6: 1 | P6: sinf | Q6: =IF(ISBLANK(G2),"",G2) | R6: =IF(ISBLANK($B6),"",$B6) -> 1 | S6: =IF(ISBLANK($C6),"",$C6) | AA6: =IF(ISBLANK($D6),"",$D6) | AB6: =IF(OR(ISBLANK(AA6),AA6=""),"",AA6*100/AA$2) | AC6: =IF(ISBLANK($B6),"",$B6) -> 1 | AD6: =IF(ISBLANK($C6),"",$C6) | AL6: =IF(ISBLANK($E6),"",$E6) | AM6: =IF(OR(ISBLANK(AL6),AL6=""),"",AL6*100/AL$2) | AN6: =IF(ISBLANK($B6),"",$B6) -> 1 | AO6: =IF(ISBLANK($C6),"",$C6) | AW6: =IF(ISBLANK($F6),"",$F6) | AX6: =IF(OR(ISBLANK(AW6),AW6=""),"",AW6*100/AW$2) | AY6: =IF(ISBLANK($B6),"",$B6) -> 1 | AZ6: =IF(ISBLANK($C6),"",$C6) | BH6: =IF(ISBLANK($G6),"",$G6) | BI6: =IF(OR(ISBLANK(BH6),BH6=""),"",BH6*100/BH$2) | BJ6: =IF(ISBLANK($B6),"",$B6) -> 1 | BK6: =IF(ISBLANK($C6),"",$C6) | CA6: =IF(ISBLANK($I6),"",$I6) | CB6: =IF(OR(ISBLANK(CA6),CA6=""),"",CA6*100/CA$2) | CC6: =IF(ISBLANK($B6),"",$B6) -> 1 | CD6: =IF(ISBLANK($C6),"",$C6) | CH6: =IF(ISBLANK($I6),"",$I6) | CI6: =IF(OR(ISBLANK(CH6),CH6=""),"",CH6*100/CH$2)
B7: 2 | P7: chorak | Q7: 1 | R7: =IF(ISBLANK($B7),"",$B7) -> 2 | S7: =IF(ISBLANK($C7),"",$C7) | AA7: =IF(ISBLANK($D7),"",$D7) | AB7: =IF(OR(ISBLANK(AA7),AA7=""),"",AA7*100/AA$2) | AC7: =IF(ISBLANK($B7),"",$B7) -> 2 | AD7: =IF(ISBLANK($C7),"",$C7) | AL7: =IF(ISBLANK($E7),"",$E7) | AM7: =IF(OR(ISBLANK(AL7),AL7=""),"",AL7*100/AL$2) | AN7: =IF(ISBLANK($B7),"",$B7) -> 2 | AO7: =IF(ISBLANK($C7),"",$C7) | AW7: =IF(ISBLANK($F7),"",$F7) | AX7: =IF(OR(ISBLANK(AW7),AW7=""),"",AW7*100/AW$2) | AY7: =IF(ISBLANK($B7),"",$B7) -> 2 | AZ7: =IF(ISBLANK($C7),"",$C7) | BH7: =IF(ISBLANK($G7),"",$G7) | BI7: =IF(OR(ISBLANK(BH7),BH7=""),"",BH7*100/BH$2) | BJ7: =IF(ISBLANK($B7),"",$B7) -> 2 | BK7: =IF(ISBLANK($C7),"",$C7) | CA7: =IF(ISBLANK($I7),"",$I7) | CB7: =IF(OR(ISBLANK(CA7),CA7=""),"",CA7*100/CA$2) | CC7: =IF(ISBLANK($B7),"",$B7) -> 2 | CD7: =IF(ISBLANK($C7),"",$C7) | CH7: =IF(ISBLANK($I7),"",$I7) | CI7: =IF(OR(ISBLANK(CH7),CH7=""),"",CH7*100/CH$2)
B8: 3 | P8: o'rtacha | Q8: =IF(ISBLANK(C6),"",AVERAGE(J6:J45)) | R8: =IF(ISBLANK($B8),"",$B8) -> 3 | S8: =IF(ISBLANK($C8),"",$C8) | AA8: =IF(ISBLANK($D8),"",$D8) | AB8: =IF(OR(ISBLANK(AA8),AA8=""),"",AA8*100/AA$2) | AC8: =IF(ISBLANK($B8),"",$B8) -> 3 | AD8: =IF(ISBLANK($C8),"",$C8) | AL8: =IF(ISBLANK($E8),"",$E8) | AM8: =IF(OR(ISBLANK(AL8),AL8=""),"",AL8*100/AL$2) | AN8: =IF(ISBLANK($B8),"",$B8) -> 3 | AO8: =IF(ISBLANK($C8),"",$C8) | AW8: =IF(ISBLANK($F8),"",$F8) | AX8: =IF(OR(ISBLANK(AW8),AW8=""),"",AW8*100/AW$2) | AY8: =IF(ISBLANK($B8),"",$B8) -> 3 | AZ8: =IF(ISBLANK($C8),"",$C8) | BH8: =IF(ISBLANK($G8),"",$G8) | BI8: =IF(OR(ISBLANK(BH8),BH8=""),"",BH8*100/BH$2) | BJ8: =IF(ISBLANK($B8),"",$B8) -> 3 | BK8: =IF(ISBLANK($C8),"",$C8) | CA8: =IF(ISBLANK($I8),"",$I8) | CB8: =IF(OR(ISBLANK(CA8),CA8=""),"",CA8*100/CA$2) | CC8: =IF(ISBLANK($B8),"",$B8) -> 3 | CD8: =IF(ISBLANK($C8),"",$C8) | CH8: =IF(ISBLANK($I8),"",$I8) | CI8: =IF(OR(ISBLANK(CH8),CH8=""),"",CH8*100/CH$2)
B9: 4 | P9: 5 baholar | Q9: =IF(ISBLANK(C6),"",COUNTIF(O6:O45,5)) | R9: =IF(ISBLANK($B9),"",$B9) -> 4 | S9: =IF(ISBLANK($C9),"",$C9) | AA9: =IF(ISBLANK($D9),"",$D9) | AB9: =IF(OR(ISBLANK(AA9),AA9=""),"",AA9*100/AA$2) | AC9: =IF(ISBLANK($B9),"",$B9) -> 4 | AD9: =IF(ISBLANK($C9),"",$C9) | AL9: =IF(ISBLANK($E9),"",$E9) | AM9: =IF(OR(ISBLANK(AL9),AL9=""),"",AL9*100/AL$2) | AN9: =IF(ISBLANK($B9),"",$B9) -> 4 | AO9: =IF(ISBLANK($C9),"",$C9) | AW9: =IF(ISBLANK($F9),"",$F9) | AX9: =IF(OR(ISBLANK(AW9),AW9=""),"",AW9*100/AW$2) | AY9: =IF(ISBLANK($B9),"",$B9) -> 4 | AZ9: =IF(ISBLANK($C9),"",$C9) | BH9: =IF(ISBLANK($G9),"",$G9) | BI9: =IF(OR(ISBLANK(BH9),BH9=""),"",BH9*100/BH$2) | BJ9: =IF(ISBLANK($B9),"",$B9) -> 4 | BK9: =IF(ISBLANK($C9),"",$C9) | CA9: =IF(ISBLANK($I9),"",$I9) | CB9: =IF(OR(ISBLANK(CA9),CA9=""),"",CA9*100/CA$2) | CC9: =IF(ISBLANK($B9),"",$B9) -> 4 | CD9: =IF(ISBLANK($C9),"",$C9) | CH9: =IF(ISBLANK($I9),"",$I9) | CI9: =IF(OR(ISBLANK(CH9),CH9=""),"",CH9*100/CH$2)
B10: 5 | P10: 4 baholar | Q10: =IF(ISBLANK(C6),"",COUNTIF(O6:O45,4)) | R10: =IF(ISBLANK($B10),"",$B10) -> 5 | S10: =IF(ISBLANK($C10),"",$C10) | AA10: =IF(ISBLANK($D10),"",$D10) | AB10: =IF(OR(ISBLANK(AA10),AA10=""),"",AA10*100/AA$2) | AC10: =IF(ISBLANK($B10),"",$B10) -> 5 | AD10: =IF(ISBLANK($C10),"",$C10) | AL10: =IF(ISBLANK($E10),"",$E10) | AM10: =IF(OR(ISBLANK(AL10),AL10=""),"",AL10*100/AL$2) | AN10: =IF(ISBLANK($B10),"",$B10) -> 5 | AO10: =IF(ISBLANK($C10),"",$C10) | AW10: =IF(ISBLANK($F10),"",$F10) | AX10: =IF(OR(ISBLANK(AW10),AW10=""),"",AW10*100/AW$2) | AY10: =IF(ISBLANK($B10),"",$B10) -> 5 | AZ10: =IF(ISBLANK($C10),"",$C10) | BH10: =IF(ISBLANK($G10),"",$G10) | BI10: =IF(OR(ISBLANK(BH10),BH10=""),"",BH10*100/BH$2) | BJ10: =IF(ISBLANK($B10),"",$B10) -> 5 | BK10: =IF(ISBLANK($C10),"",$C10) | CA10: =IF(ISBLANK($I10),"",$I10) | CB10: =IF(OR(ISBLANK(CA10),CA10=""),"",CA10*100/CA$2) | CC10: =IF(ISBLANK($B10),"",$B10) -> 5 | CD10: =IF(ISBLANK($C10),"",$C10) | CH10: =IF(ISBLANK($I10),"",$I10) | CI10: =IF(OR(ISBLANK(CH10),CH10=""),"",CH10*100/CH$2)
B11: 6 | P11: 3 baholar | Q11: =IF(ISBLANK(C6),"",COUNTIF(O6:O45,3)) | R11: =IF(ISBLANK($B11),"",$B11) -> 6 | S11: =IF(ISBLANK($C11),"",$C11) | AA11: =IF(ISBLANK($D11),"",$D11) | AB11: =IF(OR(ISBLANK(AA11),AA11=""),"",AA11*100/AA$2) | AC11: =IF(ISBLANK($B11),"",$B11) -> 6 | AD11: =IF(ISBLANK($C11),"",$C11) | AL11: =IF(ISBLANK($E11),"",$E11) | AM11: =IF(OR(ISBLANK(AL11),AL11=""),"",AL11*100/AL$2) | AN11: =IF(ISBLANK($B11),"",$B11) -> 6 | AO11: =IF(ISBLANK($C11),"",$C11) | AW11: =IF(ISBLANK($F11),"",$F11) | AX11: =IF(OR(ISBLANK(AW11),AW11=""),"",AW11*100/AW$2) | AY11: =IF(ISBLANK($B11),"",$B11) -> 6 | AZ11: =IF(ISBLANK($C11),"",$C11) | BH11: =IF(ISBLANK($G11),"",$G11) | BI11: =IF(OR(ISBLANK(BH11),BH11=""),"",BH11*100/BH$2) | BJ11: =IF(ISBLANK($B11),"",$B11) -> 6 | BK11: =IF(ISBLANK($C11),"",$C11) | CA11: =IF(ISBLANK($I11),"",$I11) | CB11: =IF(OR(ISBLANK(CA11),CA11=""),"",CA11*100/CA$2) | CC11: =IF(ISBLANK($B11),"",$B11) -> 6 | CD11: =IF(ISBLANK($C11),"",$C11) | CH11: =IF(ISBLANK($I11),"",$I11) | CI11: =IF(OR(ISBLANK(CH11),CH11=""),"",CH11*100/CH$2)
B12: 7 | P12: eng yuqori | Q12: =IF(ISBLANK(C6),"",MAX(J6:J45)) | R12: =IF(ISBLANK($B12),"",$B12) -> 7 | S12: =IF(ISBLANK($C12),"",$C12) | AA12: =IF(ISBLANK($D12),"",$D12) | AB12: =IF(OR(ISBLANK(AA12),AA12=""),"",AA12*100/AA$2) | AC12: =IF(ISBLANK($B12),"",$B12) -> 7 | AD12: =IF(ISBLANK($C12),"",$C12) | AL12: =IF(ISBLANK($E12),"",$E12) | AM12: =IF(OR(ISBLANK(AL12),AL12=""),"",AL12*100/AL$2) | AN12: =IF(ISBLANK($B12),"",$B12) -> 7 | AO12: =IF(ISBLANK($C12),"",$C12) | AW12: =IF(ISBLANK($F12),"",$F12) | AX12: =IF(OR(ISBLANK(AW12),AW12=""),"",AW12*100/AW$2) | AY12: =IF(ISBLANK($B12),"",$B12) -> 7 | AZ12: =IF(ISBLANK($C12),"",$C12) | BH12: =IF(ISBLANK($G12),"",$G12) | BI12: =IF(OR(ISBLANK(BH12),BH12=""),"",BH12*100/BH$2) | BJ12: =IF(ISBLANK($B12),"",$B12) -> 7 | BK12: =IF(ISBLANK($C12),"",$C12) | CA12: =IF(ISBLANK($I12),"",$I12) | CB12: =IF(OR(ISBLANK(CA12),CA12=""),"",CA12*100/CA$2) | CC12: =IF(ISBLANK($B12),"",$B12) -> 7 | CD12: =IF(ISBLANK($C12),"",$C12) | CH12: =IF(ISBLANK($I12),"",$I12) | CI12: =IF(OR(ISBLANK(CH12),CH12=""),"",CH12*100/CH$2)
B13: 8 | P13: eng past | Q13: =IF(ISBLANK(C6),"",MIN(J6:J45)) | R13: =IF(ISBLANK($B13),"",$B13) -> 8 | S13: =IF(ISBLANK($C13),"",$C13) | AA13: =IF(ISBLANK($D13),"",$D13) | AB13: =IF(OR(ISBLANK(AA13),AA13=""),"",AA13*100/AA$2) | AC13: =IF(ISBLANK($B13),"",$B13) -> 8 | AD13: =IF(ISBLANK($C13),"",$C13) | AL13: =IF(ISBLANK($E13),"",$E13) | AM13: =IF(OR(ISBLANK(AL13),AL13=""),"",AL13*100/AL$2) | AN13: =IF(ISBLANK($B13),"",$B13) -> 8 | AO13: =IF(ISBLANK($C13),"",$C13) | AW13: =IF(ISBLANK($F13),"",$F13) | AX13: =IF(OR(ISBLANK(AW13),AW13=""),"",AW13*100/AW$2) | AY13: =IF(ISBLANK($B13),"",$B13) -> 8 | AZ13: =IF(ISBLANK($C13),"",$C13) | BH13: =IF(ISBLANK($G13),"",$G13) | BI13: =IF(OR(ISBLANK(BH13),BH13=""),"",BH13*100/BH$2) | BJ13: =IF(ISBLANK($B13),"",$B13) -> 8 | BK13: =IF(ISBLANK($C13),"",$C13) | CA13: =IF(ISBLANK($I13),"",$I13) | CB13: =IF(OR(ISBLANK(CA13),CA13=""),"",CA13*100/CA$2) | CC13: =IF(ISBLANK($B13),"",$B13) -> 8 | CD13: =IF(ISBLANK($C13),"",$C13) | CH13: =IF(ISBLANK($I13),"",$I13) | CI13: =IF(OR(ISBLANK(CH13),CH13=""),"",CH13*100/CH$2)
B14: 9 | R14: =IF(ISBLANK($B14),"",$B14) -> 9 | S14: =IF(ISBLANK($C14),"",$C14) | AA14: =IF(ISBLANK($D14),"",$D14) | AB14: =IF(OR(ISBLANK(AA14),AA14=""),"",AA14*100/AA$2) | AC14: =IF(ISBLANK($B14),"",$B14) -> 9 | AD14: =IF(ISBLANK($C14),"",$C14) | AL14: =IF(ISBLANK($E14),"",$E14) | AM14: =IF(OR(ISBLANK(AL14),AL14=""),"",AL14*100/AL$2) | AN14: =IF(ISBLANK($B14),"",$B14) -> 9 | AO14: =IF(ISBLANK($C14),"",$C14) | AW14: =IF(ISBLANK($F14),"",$F14) | AX14: =IF(OR(ISBLANK(AW14),AW14=""),"",AW14*100/AW$2) | AY14: =IF(ISBLANK($B14),"",$B14) -> 9 | AZ14: =IF(ISBLANK($C14),"",$C14) | BH14: =IF(ISBLANK($G14),"",$G14) | BI14: =IF(OR(ISBLANK(BH14),BH14=""),"",BH14*100/BH$2) | BJ14: =IF(ISBLANK($B14),"",$B14) -> 9 | BK14: =IF(ISBLANK($C14),"",$C14) | CA14: =IF(ISBLANK($I14),"",$I14) | CB14: =IF(OR(ISBLANK(CA14),CA14=""),"",CA14*100/CA$2) | CC14: =IF(ISBLANK($B14),"",$B14) -> 9 | CD14: =IF(ISBLANK($C14),"",$C14) | CH14: =IF(ISBLANK($I14),"",$I14) | CI14: =IF(OR(ISBLANK(CH14),CH14=""),"",CH14*100/CH$2)
B15: 10 | R15: =IF(ISBLANK($B15),"",$B15) -> 10 | S15: =IF(ISBLANK($C15),"",$C15) | AA15: =IF(ISBLANK($D15),"",$D15) | AB15: =IF(OR(ISBLANK(AA15),AA15=""),"",AA15*100/AA$2) | AC15: =IF(ISBLANK($B15),"",$B15) -> 10 | AD15: =IF(ISBLANK($C15),"",$C15) | AL15: =IF(ISBLANK($E15),"",$E15) | AM15: =IF(OR(ISBLANK(AL15),AL15=""),"",AL15*100/AL$2) | AN15: =IF(ISBLANK($B15),"",$B15) -> 10 | AO15: =IF(ISBLANK($C15),"",$C15) | AW15: =IF(ISBLANK($F15),"",$F15) | AX15: =IF(OR(ISBLANK(AW15),AW15=""),"",AW15*100/AW$2) | AY15: =IF(ISBLANK($B15),"",$B15) -> 10 | AZ15: =IF(ISBLANK($C15),"",$C15) | BH15: =IF(ISBLANK($G15),"",$G15) | BI15: =IF(OR(ISBLANK(BH15),BH15=""),"",BH15*100/BH$2) | BJ15: =IF(ISBLANK($B15),"",$B15) -> 10 | BK15: =IF(ISBLANK($C15),"",$C15) | CA15: =IF(ISBLANK($I15),"",$I15) | CB15: =IF(OR(ISBLANK(CA15),CA15=""),"",CA15*100/CA$2) | CC15: =IF(ISBLANK($B15),"",$B15) -> 10 | CD15: =IF(ISBLANK($C15),"",$C15) | CH15: =IF(ISBLANK($I15),"",$I15) | CI15: =IF(OR(ISBLANK(CH15),CH15=""),"",CH15*100/CH$2)
B16: 11 | R16: =IF(ISBLANK($B16),"",$B16) -> 11 | S16: =IF(ISBLANK($C16),"",$C16) | AA16: =IF(ISBLANK($D16),"",$D16) | AB16: =IF(OR(ISBLANK(AA16),AA16=""),"",AA16*100/AA$2) | AC16: =IF(ISBLANK($B16),"",$B16) -> 11 | AD16: =IF(ISBLANK($C16),"",$C16) | AL16: =IF(ISBLANK($E16),"",$E16) | AM16: =IF(OR(ISBLANK(AL16),AL16=""),"",AL16*100/AL$2) | AN16: =IF(ISBLANK($B16),"",$B16) -> 11 | AO16: =IF(ISBLANK($C16),"",$C16) | AW16: =IF(ISBLANK($F16),"",$F16) | AX16: =IF(OR(ISBLANK(AW16),AW16=""),"",AW16*100/AW$2) | AY16: =IF(ISBLANK($B16),"",$B16) -> 11 | AZ16: =IF(ISBLANK($C16),"",$C16) | BH16: =IF(ISBLANK($G16),"",$G16) | BI16: =IF(OR(ISBLANK(BH16),BH16=""),"",BH16*100/BH$2) | BJ16: =IF(ISBLANK($B16),"",$B16) -> 11 | BK16: =IF(ISBLANK($C16),"",$C16) | CA16: =IF(ISBLANK($I16),"",$I16) | CB16: =IF(OR(ISBLANK(CA16),CA16=""),"",CA16*100/CA$2) | CC16: =IF(ISBLANK($B16),"",$B16) -> 11 | CD16: =IF(ISBLANK($C16),"",$C16) | CH16: =IF(ISBLANK($I16),"",$I16) | CI16: =IF(OR(ISBLANK(CH16),CH16=""),"",CH16*100/CH$2)
B17: 12 | R17: =IF(ISBLANK($B17),"",$B17) -> 12 | S17: =IF(ISBLANK($C17),"",$C17) | AA17: =IF(ISBLANK($D17),"",$D17) | AB17: =IF(OR(ISBLANK(AA17),AA17=""),"",AA17*100/AA$2) | AC17: =IF(ISBLANK($B17),"",$B17) -> 12 | AD17: =IF(ISBLANK($C17),"",$C17) | AL17: =IF(ISBLANK($E17),"",$E17) | AM17: =IF(OR(ISBLANK(AL17),AL17=""),"",AL17*100/AL$2) | AN17: =IF(ISBLANK($B17),"",$B17) -> 12 | AO17: =IF(ISBLANK($C17),"",$C17) | AW17: =IF(ISBLANK($F17),"",$F17) | AX17: =IF(OR(ISBLANK(AW17),AW17=""),"",AW17*100/AW$2) | AY17: =IF(ISBLANK($B17),"",$B17) -> 12 | AZ17: =IF(ISBLANK($C17),"",$C17) | BH17: =IF(ISBLANK($G17),"",$G17) | BI17: =IF(OR(ISBLANK(BH17),BH17=""),"",BH17*100/BH$2) | BJ17: =IF(ISBLANK($B17),"",$B17) -> 12 | BK17: =IF(ISBLANK($C17),"",$C17) | CA17: =IF(ISBLANK($I17),"",$I17) | CB17: =IF(OR(ISBLANK(CA17),CA17=""),"",CA17*100/CA$2) | CC17: =IF(ISBLANK($B17),"",$B17) -> 12 | CD17: =IF(ISBLANK($C17),"",$C17) | CH17: =IF(ISBLANK($I17),"",$I17) | CI17: =IF(OR(ISBLANK(CH17),CH17=""),"",CH17*100/CH$2)
B18: 13 | R18: =IF(ISBLANK($B18),"",$B18) -> 13 | S18: =IF(ISBLANK($C18),"",$C18) | AA18: =IF(ISBLANK($D18),"",$D18) | AB18: =IF(OR(ISBLANK(AA18),AA18=""),"",AA18*100/AA$2) | AC18: =IF(ISBLANK($B18),"",$B18) -> 13 | AD18: =IF(ISBLANK($C18),"",$C18) | AL18: =IF(ISBLANK($E18),"",$E18) | AM18: =IF(OR(ISBLANK(AL18),AL18=""),"",AL18*100/AL$2) | AN18: =IF(ISBLANK($B18),"",$B18) -> 13 | AO18: =IF(ISBLANK($C18),"",$C18) | AW18: =IF(ISBLANK($F18),"",$F18) | AX18: =IF(OR(ISBLANK(AW18),AW18=""),"",AW18*100/AW$2) | AY18: =IF(ISBLANK($B18),"",$B18) -> 13 | AZ18: =IF(ISBLANK($C18),"",$C18) | BH18: =IF(ISBLANK($G18),"",$G18) | BI18: =IF(OR(ISBLANK(BH18),BH18=""),"",BH18*100/BH$2) | BJ18: =IF(ISBLANK($B18),"",$B18) -> 13 | BK18: =IF(ISBLANK($C18),"",$C18) | CA18: =IF(ISBLANK($I18),"",$I18) | CB18: =IF(OR(ISBLANK(CA18),CA18=""),"",CA18*100/CA$2) | CC18: =IF(ISBLANK($B18),"",$B18) -> 13 | CD18: =IF(ISBLANK($C18),"",$C18) | CH18: =IF(ISBLANK($I18),"",$I18) | CI18: =IF(OR(ISBLANK(CH18),CH18=""),"",CH18*100/CH$2)
B19: 14 | R19: =IF(ISBLANK($B19),"",$B19) -> 14 | S19: =IF(ISBLANK($C19),"",$C19) | AA19: =IF(ISBLANK($D19),"",$D19) | AB19: =IF(OR(ISBLANK(AA19),AA19=""),"",AA19*100/AA$2) | AC19: =IF(ISBLANK($B19),"",$B19) -> 14 | AD19: =IF(ISBLANK($C19),"",$C19) | AL19: =IF(ISBLANK($E19),"",$E19) | AM19: =IF(OR(ISBLANK(AL19),AL19=""),"",AL19*100/AL$2) | AN19: =IF(ISBLANK($B19),"",$B19) -> 14 | AO19: =IF(ISBLANK($C19),"",$C19) | AW19: =IF(ISBLANK($F19),"",$F19) | AX19: =IF(OR(ISBLANK(AW19),AW19=""),"",AW19*100/AW$2) | AY19: =IF(ISBLANK($B19),"",$B19) -> 14 | AZ19: =IF(ISBLANK($C19),"",$C19) | BH19: =IF(ISBLANK($G19),"",$G19) | BI19: =IF(OR(ISBLANK(BH19),BH19=""),"",BH19*100/BH$2) | BJ19: =IF(ISBLANK($B19),"",$B19) -> 14 | BK19: =IF(ISBLANK($C19),"",$C19) | CA19: =IF(ISBLANK($I19),"",$I19) | CB19: =IF(OR(ISBLANK(CA19),CA19=""),"",CA19*100/CA$2) | CC19: =IF(ISBLANK($B19),"",$B19) -> 14 | CD19: =IF(ISBLANK($C19),"",$C19) | CH19: =IF(ISBLANK($I19),"",$I19) | CI19: =IF(OR(ISBLANK(CH19),CH19=""),"",CH19*100/CH$2)
B20: 15 | R20: =IF(ISBLANK($B20),"",$B20) -> 15 | S20: =IF(ISBLANK($C20),"",$C20) | AA20: =IF(ISBLANK($D20),"",$D20) | AB20: =IF(OR(ISBLANK(AA20),AA20=""),"",AA20*100/AA$2) | AC20: =IF(ISBLANK($B20),"",$B20) -> 15 | AD20: =IF(ISBLANK($C20),"",$C20) | AL20: =IF(ISBLANK($E20),"",$E20) | AM20: =IF(OR(ISBLANK(AL20),AL20=""),"",AL20*100/AL$2) | AN20: =IF(ISBLANK($B20),"",$B20) -> 15 | AO20: =IF(ISBLANK($C20),"",$C20) | AW20: =IF(ISBLANK($F20),"",$F20) | AX20: =IF(OR(ISBLANK(AW20),AW20=""),"",AW20*100/AW$2) | AY20: =IF(ISBLANK($B20),"",$B20) -> 15 | AZ20: =IF(ISBLANK($C20),"",$C20) | BH20: =IF(ISBLANK($G20),"",$G20) | BI20: =IF(OR(ISBLANK(BH20),BH20=""),"",BH20*100/BH$2) | BJ20: =IF(ISBLANK($B20),"",$B20) -> 15 | BK20: =IF(ISBLANK($C20),"",$C20) | CA20: =IF(ISBLANK($I20),"",$I20) | CB20: =IF(OR(ISBLANK(CA20),CA20=""),"",CA20*100/CA$2) | CC20: =IF(ISBLANK($B20),"",$B20) -> 15 | CD20: =IF(ISBLANK($C20),"",$C20) | CH20: =IF(ISBLANK($I20),"",$I20) | CI20: =IF(OR(ISBLANK(CH20),CH20=""),"",CH20*100/CH$2)
B21: 16 | R21: =IF(ISBLANK($B21),"",$B21) -> 16 | S21: =IF(ISBLANK($C21),"",$C21) | AA21: =IF(ISBLANK($D21),"",$D21) | AB21: =IF(OR(ISBLANK(AA21),AA21=""),"",AA21*100/AA$2) | AC21: =IF(ISBLANK($B21),"",$B21) -> 16 | AD21: =IF(ISBLANK($C21),"",$C21) | AL21: =IF(ISBLANK($E21),"",$E21) | AM21: =IF(OR(ISBLANK(AL21),AL21=""),"",AL21*100/AL$2) | AN21: =IF(ISBLANK($B21),"",$B21) -> 16 | AO21: =IF(ISBLANK($C21),"",$C21) | AW21: =IF(ISBLANK($F21),"",$F21) | AX21: =IF(OR(ISBLANK(AW21),AW21=""),"",AW21*100/AW$2) | AY21: =IF(ISBLANK($B21),"",$B21) -> 16 | AZ21: =IF(ISBLANK($C21),"",$C21) | BH21: =IF(ISBLANK($G21),"",$G21) | BI21: =IF(OR(ISBLANK(BH21),BH21=""),"",BH21*100/BH$2) | BJ21: =IF(ISBLANK($B21),"",$B21) -> 16 | BK21: =IF(ISBLANK($C21),"",$C21) | CA21: =IF(ISBLANK($I21),"",$I21) | CB21: =IF(OR(ISBLANK(CA21),CA21=""),"",CA21*100/CA$2) | CC21: =IF(ISBLANK($B21),"",$B21) -> 16 | CD21: =IF(ISBLANK($C21),"",$C21) | CH21: =IF(ISBLANK($I21),"",$I21) | CI21: =IF(OR(ISBLANK(CH21),CH21=""),"",CH21*100/CH$2)
B22: 17 | R22: =IF(ISBLANK($B22),"",$B22) -> 17 | S22: =IF(ISBLANK($C22),"",$C22) | AA22: =IF(ISBLANK($D22),"",$D22) | AB22: =IF(OR(ISBLANK(AA22),AA22=""),"",AA22*100/AA$2) | AC22: =IF(ISBLANK($B22),"",$B22) -> 17 | AD22: =IF(ISBLANK($C22),"",$C22) | AL22: =IF(ISBLANK($E22),"",$E22) | AM22: =IF(OR(ISBLANK(AL22),AL22=""),"",AL22*100/AL$2) | AN22: =IF(ISBLANK($B22),"",$B22) -> 17 | AO22: =IF(ISBLANK($C22),"",$C22) | AW22: =IF(ISBLANK($F22),"",$F22) | AX22: =IF(OR(ISBLANK(AW22),AW22=""),"",AW22*100/AW$2) | AY22: =IF(ISBLANK($B22),"",$B22) -> 17 | AZ22: =IF(ISBLANK($C22),"",$C22) | BH22: =IF(ISBLANK($G22),"",$G22) | BI22: =IF(OR(ISBLANK(BH22),BH22=""),"",BH22*100/BH$2) | BJ22: =IF(ISBLANK($B22),"",$B22) -> 17 | BK22: =IF(ISBLANK($C22),"",$C22) | CA22: =IF(ISBLANK($I22),"",$I22) | CB22: =IF(OR(ISBLANK(CA22),CA22=""),"",CA22*100/CA$2) | CC22: =IF(ISBLANK($B22),"",$B22) -> 17 | CD22: =IF(ISBLANK($C22),"",$C22) | CH22: =IF(ISBLANK($I22),"",$I22) | CI22: =IF(OR(ISBLANK(CH22),CH22=""),"",CH22*100/CH$2)
B23: 18 | R23: =IF(ISBLANK($B23),"",$B23) -> 18 | S23: =IF(ISBLANK($C23),"",$C23) | AA23: =IF(ISBLANK($D23),"",$D23) | AB23: =IF(OR(ISBLANK(AA23),AA23=""),"",AA23*100/AA$2) | AC23: =IF(ISBLANK($B23),"",$B23) -> 18 | AD23: =IF(ISBLANK($C23),"",$C23) | AL23: =IF(ISBLANK($E23),"",$E23) | AM23: =IF(OR(ISBLANK(AL23),AL23=""),"",AL23*100/AL$2) | AN23: =IF(ISBLANK($B23),"",$B23) -> 18 | AO23: =IF(ISBLANK($C23),"",$C23) | AW23: =IF(ISBLANK($F23),"",$F23) | AX23: =IF(OR(ISBLANK(AW23),AW23=""),"",AW23*100/AW$2) | AY23: =IF(ISBLANK($B23),"",$B23) -> 18 | AZ23: =IF(ISBLANK($C23),"",$C23) | BH23: =IF(ISBLANK($G23),"",$G23) | BI23: =IF(OR(ISBLANK(BH23),BH23=""),"",BH23*100/BH$2) | BJ23: =IF(ISBLANK($B23),"",$B23) -> 18 | BK23: =IF(ISBLANK($C23),"",$C23) | CA23: =IF(ISBLANK($I23),"",$I23) | CB23: =IF(OR(ISBLANK(CA23),CA23=""),"",CA23*100/CA$2) | CC23: =IF(ISBLANK($B23),"",$B23) -> 18 | CD23: =IF(ISBLANK($C23),"",$C23) | CH23: =IF(ISBLANK($I23),"",$I23) | CI23: =IF(OR(ISBLANK(CH23),CH23=""),"",CH23*100/CH$2)
B24: 19 | R24: =IF(ISBLANK($B24),"",$B24) -> 19 | S24: =IF(ISBLANK($C24),"",$C24) | AA24: =IF(ISBLANK($D24),"",$D24) | AB24: =IF(OR(ISBLANK(AA24),AA24=""),"",AA24*100/AA$2) | AC24: =IF(ISBLANK($B24),"",$B24) -> 19 | AD24: =IF(ISBLANK($C24),"",$C24) | AL24: =IF(ISBLANK($E24),"",$E24) | AM24: =IF(OR(ISBLANK(AL24),AL24=""),"",AL24*100/AL$2) | AN24: =IF(ISBLANK($B24),"",$B24) -> 19 | AO24: =IF(ISBLANK($C24),"",$C24) | AW24: =IF(ISBLANK($F24),"",$F24) | AX24: =IF(OR(ISBLANK(AW24),AW24=""),"",AW24*100/AW$2) | AY24: =IF(ISBLANK($B24),"",$B24) -> 19 | AZ24: =IF(ISBLANK($C24),"",$C24) | BH24: =IF(ISBLANK($G24),"",$G24) | BI24: =IF(OR(ISBLANK(BH24),BH24=""),"",BH24*100/BH$2) | BJ24: =IF(ISBLANK($B24),"",$B24) -> 19 | BK24: =IF(ISBLANK($C24),"",$C24) | CA24: =IF(ISBLANK($I24),"",$I24) | CB24: =IF(OR(ISBLANK(CA24),CA24=""),"",CA24*100/CA$2) | CC24: =IF(ISBLANK($B24),"",$B24) -> 19 | CD24: =IF(ISBLANK($C24),"",$C24) | CH24: =IF(ISBLANK($I24),"",$I24) | CI24: =IF(OR(ISBLANK(CH24),CH24=""),"",CH24*100/CH$2)
B25: 20 | R25: =IF(ISBLANK($B25),"",$B25) -> 20 | S25: =IF(ISBLANK($C25),"",$C25) | AA25: =IF(ISBLANK($D25),"",$D25) | AB25: =IF(OR(ISBLANK(AA25),AA25=""),"",AA25*100/AA$2) | AC25: =IF(ISBLANK($B25),"",$B25) -> 20 | AD25: =IF(ISBLANK($C25),"",$C25) | AL25: =IF(ISBLANK($E25),"",$E25) | AM25: =IF(OR(ISBLANK(AL25),AL25=""),"",AL25*100/AL$2) | AN25: =IF(ISBLANK($B25),"",$B25) -> 20 | AO25: =IF(ISBLANK($C25),"",$C25) | AW25: =IF(ISBLANK($F25),"",$F25) | AX25: =IF(OR(ISBLANK(AW25),AW25=""),"",AW25*100/AW$2) | AY25: =IF(ISBLANK($B25),"",$B25) -> 20 | AZ25: =IF(ISBLANK($C25),"",$C25) | BH25: =IF(ISBLANK($G25),"",$G25) | BI25: =IF(OR(ISBLANK(BH25),BH25=""),"",BH25*100/BH$2) | BJ25: =IF(ISBLANK($B25),"",$B25) -> 20 | BK25: =IF(ISBLANK($C25),"",$C25) | CA25: =IF(ISBLANK($I25),"",$I25) | CB25: =IF(OR(ISBLANK(CA25),CA25=""),"",CA25*100/CA$2) | CC25: =IF(ISBLANK($B25),"",$B25) -> 20 | CD25: =IF(ISBLANK($C25),"",$C25) | CH25: =IF(ISBLANK($I25),"",$I25) | CI25: =IF(OR(ISBLANK(CH25),CH25=""),"",CH25*100/CH$2)
... B43: 38 | R43: =IF(ISBLANK($B43),"",$B43) -> 38 | S43: =IF(ISBLANK($C43),"",$C43) | AA43: =IF(ISBLANK($D43),"",$D43) | AB43: =IF(OR(ISBLANK(AA43),AA43=""),"",AA43*100/AA$2) | AC43: =IF(ISBLANK($B43),"",$B43) -> 38 | AD43: =IF(ISBLANK($C43),"",$C43) | AL43: =IF(ISBLANK($E43),"",$E43) | AM43: =IF(OR(ISBLANK(AL43),AL43=""),"",AL43*100/AL$2) | AN43: =IF(ISBLANK($B43),"",$B43) -> 38 | AO43: =IF(ISBLANK($C43),"",$C43) | AW43: =IF(ISBLANK($F43),"",$F43) | AX43: =IF(OR(ISBLANK(AW43),AW43=""),"",AW43*100/AW$2) | AY43: =IF(ISBLANK($B43),"",$B43) -> 38 | AZ43: =IF(ISBLANK($C43),"",$C43) | BH43: =IF(ISBLANK($G43),"",$G43) | BI43: =IF(OR(ISBLANK(BH43),BH43=""),"",BH43*100/BH$2) | BJ43: =IF(ISBLANK($B43),"",$B43) -> 38 | BK43: =IF(ISBLANK($C43),"",$C43) | CA43: =IF(ISBLANK($I43),"",$I43) | CB43: =IF(OR(ISBLANK(CA43),CA43=""),"",CA43*100/CA$2) | CC43: =IF(ISBLANK($B43),"",$B43) -> 38 | CD43: =IF(ISBLANK($C43),"",$C43) | CH43: =IF(ISBLANK($I43),"",$I43) | CI43: =IF(OR(ISBLANK(CH43),CH43=""),"",CH43*100/CH$2)
B44: 39 | R44: =IF(ISBLANK($B44),"",$B44) -> 39 | S44: =IF(ISBLANK($C44),"",$C44) | AA44: =IF(ISBLANK($D44),"",$D44) | AB44: =IF(OR(ISBLANK(AA44),AA44=""),"",AA44*100/AA$2) | AC44: =IF(ISBLANK($B44),"",$B44) -> 39 | AD44: =IF(ISBLANK($C44),"",$C44) | AL44: =IF(ISBLANK($E44),"",$E44) | AM44: =IF(OR(ISBLANK(AL44),AL44=""),"",AL44*100/AL$2) | AN44: =IF(ISBLANK($B44),"",$B44) -> 39 | AO44: =IF(ISBLANK($C44),"",$C44) | AW44: =IF(ISBLANK($F44),"",$F44) | AX44: =IF(OR(ISBLANK(AW44),AW44=""),"",AW44*100/AW$2) | AY44: =IF(ISBLANK($B44),"",$B44) -> 39 | AZ44: =IF(ISBLANK($C44),"",$C44) | BH44: =IF(ISBLANK($G44),"",$G44) | BI44: =IF(OR(ISBLANK(BH44),BH44=""),"",BH44*100/BH$2) | BJ44: =IF(ISBLANK($B44),"",$B44) -> 39 | BK44: =IF(ISBLANK($C44),"",$C44) | CA44: =IF(ISBLANK($I44),"",$I44) | CC44: =IF(ISBLANK($B44),"",$B44) -> 39 | CD44: =IF(ISBLANK($C44),"",$C44) | CH44: =IF(ISBLANK($I44),"",$I44)
B45: 40 | R45: =IF(ISBLANK($B45),"",$B45) -> 40 | S45: =IF(ISBLANK($C45),"",$C45) | AA45: =IF(ISBLANK($D45),"",$D45) | AB45: =IF(OR(ISBLANK(AA45),AA45=""),"",AA45*100/AA$2) | AC45: =IF(ISBLANK($B45),"",$B45) -> 40 | AD45: =IF(ISBLANK($C45),"",$C45) | AL45: =IF(ISBLANK($E45),"",$E45) | AM45: =IF(OR(ISBLANK(AL45),AL45=""),"",AL45*100/AL$2) | AN45: =IF(ISBLANK($B45),"",$B45) -> 40 | AO45: =IF(ISBLANK($C45),"",$C45) | AW45: =IF(ISBLANK($F45),"",$F45) | AX45: =IF(OR(ISBLANK(AW45),AW45=""),"",AW45*100/AW$2) | AY45: =IF(ISBLANK($B45),"",$B45) -> 40 | AZ45: =IF(ISBLANK($C45),"",$C45) | BH45: =IF(ISBLANK($G45),"",$G45) | BI45: =IF(OR(ISBLANK(BH45),BH45=""),"",BH45*100/BH$2) | BJ45: =IF(ISBLANK($B45),"",$B45) -> 40 | BK45: =IF(ISBLANK($C45),"",$C45) | CA45: =IF(ISBLANK($I45),"",$I45) | CC45: =IF(ISBLANK($B45),"",$B45) -> 40 | CD45: =IF(ISBLANK($C45),"",$C45) | CH45: =IF(ISBLANK($I45),"",$I45)
AA46: 3 | AB46: 30 | AL46: 3 | AM46: 30 | AW46: 3 | AX46: 30 | BH46: 3 | BI46: 30 | CA46: 10 | CB46: 30 | CH46: 10 | CI46: 30
R47: o'rtacha | AA47: =IF(ISBLANK(AB47),"",AB47) -> #DIV/0! | AB47: =AVERAGE(AB6:AB45) -> #DIV/0! | AC47: o'rtacha | AL47: =IF(ISBLANK(AM47),"",AM47) | AM47: =IF(ISERROR(AVERAGE(AM6:AM45)),"",AVERAGE(AM6:AM45)) | AN47: o'rtacha | AW47: =IF(ISBLANK(AX47),"",AX47) | AX47: =IF(ISERROR(AVERAGE(AX6:AX45)),"",AVERAGE(AX6:AX45)) | AY47: o'rtacha | BH47: =IF(ISBLANK(BI47),"",BI47) | BI47: =IF(ISERROR(AVERAGE(BI6:BI45)),"",AVERAGE(BI6:BI45)) | BJ47: o'rtacha | CA47: =IF(ISBLANK(CB47),"",CB47) | CB47: =IF(ISERROR(AVERAGE(CB6:CB45)),"",AVERAGE(CB6:CB45)) | CC47: o'rtacha | CH47: =IF(ISBLANK(CI47),"",CI47) | CI47: =IF(ISERROR(AVERAGE(CI6:CI45)),"",AVERAGE(CI6:CI45))
C48: Fan o`qituvchisi:
R49: Fan o`qituvchisi: _____________________________________ | T49: =IF(ISBLANK($G48),"",$G48) | AC49: Fan o`qituvchisi: _____________________________________ | AE49: =IF(ISBLANK($G48),"",$G48) | AN49: Fan o`qituvchisi: _____________________________________ | AP49: =IF(ISBLANK($G48),"",$G48) | AY49: Fan o`qituvchisi: _____________________________________ | BA49: =IF(ISBLANK($G48),"",$G48) | BJ49: Fan o`qituvchisi: _____________________________________ | BP49: =IF(ISBLANK($G48),"",$G48) | CC49: Fan o`qituvchisi: _____________________________________ | CE49: =IF(ISBLANK($G48),"",$G48)
B50: CHORAKLIK NATIJALAR | R50: _________________ kuni olingan ____BSB/Loyiha ishi NATIJALARI | AC50: _________________ kuni olingan ____BSB/Loyiha ishi NATIJALARI | AN50: _________________ kuni olingan ____BSB/Loyiha ishi NATIJALARI | AY50: _________________ kuni olingan ____BSB/Loyiha ishi NATIJALARI | BJ50: _________________ kuni olingan ____CHSB NATIJALARI | CC50: _________________ kuni olingan ____CHSB NATIJALARI
B51: fan | D51: chorak | F51: sinf | R51: =$B$2 -> fan | S51: =$C$2 -> 0 | T51: =$D$2 -> chorak | U51: =$E$2 -> 0 | V51: =$F$2 -> sinf | W51: =$G$2 -> 0 | AA51: =IF(MAX(AA55:AA94)>40,50,IF(MAX(AA55:AA94)>20,25,IF(MAX(AA55:AA94)>15,20,IF(MAX(AA55:AA94)>8,10)))) -> FALSE | AB51: ball | AC51: =$B$2 -> fan | AD51: =$C$2 -> 0 | AE51: =$D$2 -> chorak | AF51: =$E$2 -> 0 | AG51: =$F$2 -> sinf | AH51: =$G$2 -> 0 | AL51: =IF(MAX(AL55:AL94)>40,50,IF(MAX(AL55:AL94)>20,25,IF(MAX(AL55:AL94)>15,20,IF(MAX(AL55:AL94)>8,10)))) -> FALSE | AM51: ball | AN51: =$B$2 -> fan | AO51: =$C$2 -> 0 | AP51: =$D$2 -> chorak | AQ51: =$E$2 -> 0 | AR51: =$F$2 -> sinf | AS51: =$G$2 -> 0 | AW51: =IF(MAX(AW55:AW94)>40,50,IF(MAX(AW55:AW94)>20,25,IF(MAX(AW55:AW94)>15,20,IF(MAX(AW55:AW94)>8,10)))) -> FALSE | AX51: ball | AY51: =$B$2 -> fan | AZ51: =$C$2 -> 0 | BA51: =$D$2 -> chorak | BB51: =$E$2 -> 0 | BC51: =$F$2 -> sinf | BD51: =$G$2 -> 0 | BH51: =IF(MAX(BH55:BH94)>40,50,IF(MAX(BH55:BH94)>20,25,IF(MAX(BH55:BH94)>15,20,IF(MAX(BH55:BH94)>8,10)))) -> FALSE | BI51: ball | BJ51: fan | BK51: =$C$2 -> 0 | BL51: chorak | BO51: =$E$2 -> 0 | BR51: sinf | BT51: =$G$2 -> 0 | CA51: 40 | CB51: ball | CC51: fan | CD51: =$C$2 -> 0 | CE51: ="chorak: "&$E$2 -> chorak: | CG51: ="sinf: "& $G$2 -> sinf: | CH51: 40 | CI51: ball
B53: T/r | C53: F.I.SH | D53: summativ baholash bo'yicha ballar | O53: chorak bahosi | P53: fan | Q53: =IF(ISBLANK(C51),"",C51) | R53: T/r | S53: F.I.SH | T53: Baholash mezoni | AA53: Jami ball | AB53: Foizda | AC53: T/r | AD53: F.I.SH | AE53: Baholash mezoni | AL53: Jami ball | AM53: Foizda | AN53: T/r | AO53: F.I.SH | AP53: Baholash mezoni | AW53: Jami ball | AX53: Foizda | AY53: T/r | AZ53: F.I.SH | BA53: Baholash mezoni | BH53: Jami ball | BI53: Foizda | BJ53: T/r | BK53: F.I.SH | BL53: Baholash mezoni | CA53: Jami ball 40 | CB53: Foizda | CC53: T/r | CD53: F.I.SH | CE53: Baholash mezoni | CH53: Jami ball 40 | CI53: Foizda
D54: BSB | E54: BSB | F54: BSB | G54: LI/Lab | H54: FB (10) | I54: CHSB (40) | J54: Jami ball (100) | N54: tahlil % da | T54: 1 | U54: 2 | V54: 3 | W54: 4 | X54: 5 | Y54: 6 | Z54: 7 | AE54: 1 | AF54: 2 | AG54: 3 | AH54: 4 | AI54: 5 | AJ54: 6 | AK54: 7 | AP54: 1 | AQ54: 2 | AR54: 3 | AS54: 4 | AT54: 5 | AU54: 6 | AV54: 7 | BA54: 1 | BB54: 2 | BC54: 3 | BD54: 4 | BE54: 5 | BF54: 6 | BG54: 7 | BL54: 1 | BM54: 2 | BN54: 3 | BO54: 4 | BP54: 5 | BQ54: 6 | BR54: 7 | BS54: 8 | BT54: 9 | BU54: 10 | BV54: 11 | BW54: 12 | BX54: 13 | BY54: 14 | BZ54: 15 | CE54: "Bilish (to'g'ri javoblar soni)" | CF54: "qo'llash (to'g'ri javoblar soni)" | CG54: "Mulohaza (to'g'ri javoblar soni)"
B55: 1 | P55: sinf | Q55: =IF(ISBLANK(G51),"",G51) | R55: =IF(ISBLANK($B55),"",$B55) -> 1 | S55: =IF(ISBLANK($C55),"",$C55) | AA55: =IF(ISBLANK($D55),"",$D55) | AB55: =IF(OR(ISBLANK(AA55),AA55=""),"",AA55*100/AA$2) | AC55: =IF(ISBLANK($B55),"",$B55) -> 1 | AD55: =IF(ISBLANK($C55),"",$C55) | AL55: =IF(ISBLANK($E55),"",$E55) | AM55: =IF(OR(ISBLANK(AL55),AL55=""),"",AL55*100/AL$2) | AN55: =IF(ISBLANK($B55),"",$B55) -> 1 | AO55: =IF(ISBLANK($C55),"",$C55) | AW55: =IF(ISBLANK($F55),"",$F55) | AX55: =IF(OR(ISBLANK(AW55),AW55=""),"",AW55*100/AW$2) | AY55: =IF(ISBLANK($B55),"",$B55) -> 1 | AZ55: =IF(ISBLANK($C55),"",$C55) | BH55: =IF(ISBLANK($G55),"",$G55) | BI55: =IF(OR(ISBLANK(BH55),BH55=""),"",BH55*100/BH$2) | BJ55: =IF(ISBLANK($B55),"",$B55) -> 1 | BK55: =IF(ISBLANK($C55),"",$C55) | CA55: =IF(ISBLANK($I55),"",$I55) | CB55: =IF(OR(ISBLANK(CA55),CA55=""),"",CA55*100/CA$2) | CC55: =IF(ISBLANK($B55),"",$B55) -> 1 | CD55: =IF(ISBLANK($C55),"",$C55) | CH55: =IF(ISBLANK($I55),"",$I55) | CI55: =IF(OR(ISBLANK(CH55),CH55=""),"",CH55*100/CH$2)
B56: 2 | P56: chorak | Q56: 2 | R56: =IF(ISBLANK($B56),"",$B56) -> 2 | S56: =IF(ISBLANK($C56),"",$C56) | AA56: =IF(ISBLANK($D56),"",$D56) | AB56: =IF(OR(ISBLANK(AA56),AA56=""),"",AA56*100/AA$2) | AC56: =IF(ISBLANK($B56),"",$B56) -> 2 | AD56: =IF(ISBLANK($C56),"",$C56) | AL56: =IF(ISBLANK($E56),"",$E56) | AM56: =IF(OR(ISBLANK(AL56),AL56=""),"",AL56*100/AL$2) | AN56: =IF(ISBLANK($B56),"",$B56) -> 2 | AO56: =IF(ISBLANK($C56),"",$C56) | AW56: =IF(ISBLANK($F56),"",$F56) | AX56: =IF(OR(ISBLANK(AW56),AW56=""),"",AW56*100/AW$2) | AY56: =IF(ISBLANK($B56),"",$B56) -> 2 | AZ56: =IF(ISBLANK($C56),"",$C56) | BH56: =IF(ISBLANK($G56),"",$G56) | BI56: =IF(OR(ISBLANK(BH56),BH56=""),"",BH56*100/BH$2) | BJ56: =IF(ISBLANK($B56),"",$B56) -> 2 | BK56: =IF(ISBLANK($C56),"",$C56) | CA56: =IF(ISBLANK($I56),"",$I56) | CB56: =IF(OR(ISBLANK(CA56),CA56=""),"",CA56*100/CA$2) | CC56: =IF(ISBLANK($B56),"",$B56) -> 2 | CD56: =IF(ISBLANK($C56),"",$C56) | CH56: =IF(ISBLANK($I56),"",$I56) | CI56: =IF(OR(ISBLANK(CH56),CH56=""),"",CH56*100/CH$2)
B57: 3 | P57: o'rtacha | Q57: =IF(ISBLANK(C55),"",AVERAGE(J55:J94)) | R57: =IF(ISBLANK($B57),"",$B57) -> 3 | S57: =IF(ISBLANK($C57),"",$C57) | AA57: =IF(ISBLANK($D57),"",$D57) | AB57: =IF(OR(ISBLANK(AA57),AA57=""),"",AA57*100/AA$2) | AC57: =IF(ISBLANK($B57),"",$B57) -> 3 | AD57: =IF(ISBLANK($C57),"",$C57) | AL57: =IF(ISBLANK($E57),"",$E57) | AM57: =IF(OR(ISBLANK(AL57),AL57=""),"",AL57*100/AL$2) | AN57: =IF(ISBLANK($B57),"",$B57) -> 3 | AO57: =IF(ISBLANK($C57),"",$C57) | AW57: =IF(ISBLANK($F57),"",$F57) | AX57: =IF(OR(ISBLANK(AW57),AW57=""),"",AW57*100/AW$2) | AY57: =IF(ISBLANK($B57),"",$B57) -> 3 | AZ57: =IF(ISBLANK($C57),"",$C57) | BH57: =IF(ISBLANK($G57),"",$G57) | BI57: =IF(OR(ISBLANK(BH57),BH57=""),"",BH57*100/BH$2) | BJ57: =IF(ISBLANK($B57),"",$B57) -> 3 | BK57: =IF(ISBLANK($C57),"",$C57) | CA57: =IF(ISBLANK($I57),"",$I57) | CB57: =IF(OR(ISBLANK(CA57),CA57=""),"",CA57*100/CA$2) | CC57: =IF(ISBLANK($B57),"",$B57) -> 3 | CD57: =IF(ISBLANK($C57),"",$C57) | CH57: =IF(ISBLANK($I57),"",$I57) | CI57: =IF(OR(ISBLANK(CH57),CH57=""),"",CH57*100/CH$2)
B58: 4 | P58: 5 baholar | Q58: =IF(ISBLANK(C55),"",COUNTIF(O55:O94,5)) | R58: =IF(ISBLANK($B58),"",$B58) -> 4 | S58: =IF(ISBLANK($C58),"",$C58) | AA58: =IF(ISBLANK($D58),"",$D58) | AB58: =IF(OR(ISBLANK(AA58),AA58=""),"",AA58*100/AA$2) | AC58: =IF(ISBLANK($B58),"",$B58) -> 4 | AD58: =IF(ISBLANK($C58),"",$C58) | AL58: =IF(ISBLANK($E58),"",$E58) | AM58: =IF(OR(ISBLANK(AL58),AL58=""),"",AL58*100/AL$2) | AN58: =IF(ISBLANK($B58),"",$B58) -> 4 | AO58: =IF(ISBLANK($C58),"",$C58) | AW58: =IF(ISBLANK($F58),"",$F58) | AX58: =IF(OR(ISBLANK(AW58),AW58=""),"",AW58*100/AW$2) | AY58: =IF(ISBLANK($B58),"",$B58) -> 4 | AZ58: =IF(ISBLANK($C58),"",$C58) | BH58: =IF(ISBLANK($G58),"",$G58) | BI58: =IF(OR(ISBLANK(BH58),BH58=""),"",BH58*100/BH$2) | BJ58: =IF(ISBLANK($B58),"",$B58) -> 4 | BK58: =IF(ISBLANK($C58),"",$C58) | CA58: =IF(ISBLANK($I58),"",$I58) | CB58: =IF(OR(ISBLANK(CA58),CA58=""),"",CA58*100/CA$2) | CC58: =IF(ISBLANK($B58),"",$B58) -> 4 | CD58: =IF(ISBLANK($C58),"",$C58) | CH58: =IF(ISBLANK($I58),"",$I58) | CI58: =IF(OR(ISBLANK(CH58),CH58=""),"",CH58*100/CH$2)
B59: 5 | P59: 4 baholar | Q59: =IF(ISBLANK(C55),"",COUNTIF(O55:O94,4)) | R59: =IF(ISBLANK($B59),"",$B59) -> 5 | S59: =IF(ISBLANK($C59),"",$C59) | AA59: =IF(ISBLANK($D59),"",$D59) | AB59: =IF(OR(ISBLANK(AA59),AA59=""),"",AA59*100/AA$2) | AC59: =IF(ISBLANK($B59),"",$B59) -> 5 | AD59: =IF(ISBLANK($C59),"",$C59) | AL59: =IF(ISBLANK($E59),"",$E59) | AM59: =IF(OR(ISBLANK(AL59),AL59=""),"",AL59*100/AL$2) | AN59: =IF(ISBLANK($B59),"",$B59) -> 5 | AO59: =IF(ISBLANK($C59),"",$C59) | AW59: =IF(ISBLANK($F59),"",$F59) | AX59: =IF(OR(ISBLANK(AW59),AW59=""),"",AW59*100/AW$2) | AY59: =IF(ISBLANK($B59),"",$B59) -> 5 | AZ59: =IF(ISBLANK($C59),"",$C59) | BH59: =IF(ISBLANK($G59),"",$G59) | BI59: =IF(OR(ISBLANK(BH59),BH59=""),"",BH59*100/BH$2) | BJ59: =IF(ISBLANK($B59),"",$B59) -> 5 | BK59: =IF(ISBLANK($C59),"",$C59) | CA59: =IF(ISBLANK($I59),"",$I59) | CB59: =IF(OR(ISBLANK(CA59),CA59=""),"",CA59*100/CA$2) | CC59: =IF(ISBLANK($B59),"",$B59) -> 5 | CD59: =IF(ISBLANK($C59),"",$C59) | CH59: =IF(ISBLANK($I59),"",$I59) | CI59: =IF(OR(ISBLANK(CH59),CH59=""),"",CH59*100/CH$2)
...

Sheet tahlil
A2: Fan o'qituvchisi: | D2: Qodirova Gulbahor | G2: o'quv yili | H2: 2025-2026
A4: TR | B4: sinf | D4: sinf bo'yicha o'rtacha ball | K4: ASOSIY FARQ
C5: fan | D5: 1-chorak | E5: 2-chorak | F5: farq | G5: 3-chorak | H5: farq | I5: 4-chorak | J5: farq | M5: chorak | N5: 1-chorak | O5: 2-chorak | P5: 3-chorak | Q5: 4-chorak
A6: 1 | B6: =list!A199 | C6: =list!B199 | D6: =list!C199 | E6: =list!D199 | F6: =list!E199 | G6: =list!F199 | H6: =list!G199 | I6: =list!H199 | ... K6: =list!J199 -> #VALUE! | M6: o'rtacha ball | N6: =D7 -> #DIV/0! | O6: =E7 -> #DIV/0! | P6: =G7 -> #DIV/0! | Q6: =I7 -> #DIV/0!
A7: Umumiy | D7: =AVERAGE(D6:D6) -> #DIV/0! | E7: =AVERAGE(E6:E6) -> #DIV/0! | F7: =E7-D7 -> #DIV/0! | G7: =AVERAGE(G6:G6) -> #DIV/0! | H7: =G7-E7 -> #DIV/0! | I7: =AVERAGE(I6:I6) -> #DIV/0! | J7: =I7-G7 -> #DIV/0! | K7: =I7-D7 -> #DIV/0!
A9: Fan o'qituvchisi: | D9: =D2 -> Qodirova Gulbahor | G9: o'quv yili | H9: =H2 -> 2025-2026
